<?xml version="1.0"?>
<robot xmlns:xacro="http://wiki.ros.org/xacro">

  <xacro:macro name="smart_template" params="robot_mode needle_type">

    <!-- Define limit values for each needle type -->
    <xacro:property name="insertion_upper_limit" value="0.115"/>
    <xacro:if value="${needle_type == 'default'}">
      <xacro:property name="insertion_upper_limit" value="0.115"/>
    </xacro:if>
    <xacro:if value="${needle_type == 'stylet'}">
      <xacro:property name="insertion_upper_limit" value="0.115"/>
    </xacro:if>
    <xacro:if value="${needle_type == 'smartneedle'}">
      <xacro:property name="insertion_upper_limit" value="0.165"/>
    </xacro:if>
    <xacro:if value="${needle_type == 'biopsygun'}">
      <xacro:property name="insertion_upper_limit" value="0.175"/>
    </xacro:if>
    <!-- Include materials -->
    <xacro:include filename="$(find smart_template_description)/urdf/materials.xacro" />

    <!-- Define Links -->
    <link name="base_link">
      <visual>        
        <origin xyz="0 0 0" rpy="0 0 ${-pi/2}"/>
        <geometry>
          <mesh filename="package://smart_template_description/meshes/base_link.stl"/>
        </geometry>
        <material name="silver"/>
      </visual>
    </link>
    
    <link name="vertical_link">
      <visual>
        <origin xyz="0 0 0" rpy="0 0 ${-pi/2}"/>
        <geometry>
          <mesh filename="package://smart_template_description/meshes/vertical_link.stl"/>
        </geometry>
        <material name="silver"/>
      </visual>
    </link>
    
    <link name="horizontal_link">
      <visual>
        <origin xyz="0 0 0" rpy="0 0 ${-pi/2}"/>
        <geometry>
          <mesh filename="package://smart_template_description/meshes/horizontal_link.stl"/>
        </geometry>
        <material name="silver"/>
      </visual>
    </link>

    <link name="needle_link">
      <visual>
        <origin xyz="0 0 0" rpy="0 0 ${-pi/2}"/>
        <geometry>
          <mesh filename="package://smart_template_description/meshes/needle_link_${needle_type}.stl"/>
        </geometry>
        <material name="silver"/>
      </visual>
    </link>

    <!-- Define joints -->
    <joint name="vertical_joint" type="prismatic">
      <origin xyz="0 0 0" rpy="0 0 0"/>
      <parent link="base_link"/>
      <child link="vertical_link"/>
      <axis xyz="0.0 0.0 1.0"/>
      <!-- conditional limits -->
      <xacro:if value="$(eval robot_mode == 'calibration')">
        <limit upper="1e6" lower="-1e6" effort="100" velocity="1e6"/>
      </xacro:if>
      <xacro:unless value="$(eval robot_mode == 'calibration')">
        <limit upper="0.025" lower="-0.025" effort="100" velocity="100"/>
      </xacro:unless>
      <!-- custom extension -->
      <channel>C</channel>
      <mm_to_count>1430.0</mm_to_count>
    </joint>

    <joint name="horizontal_joint" type="prismatic">
      <origin xyz="0 0 0" rpy="0 0 0"/>
      <parent link="vertical_link"/>
      <child link="horizontal_link"/>
      <axis xyz="1.0 0.0 0.0"/>
      <!-- conditional limits -->
      <xacro:if value="$(eval robot_mode == 'calibration')">
        <limit upper="1e6" lower="-1e6" effort="100" velocity="1e6"/>
      </xacro:if>
      <xacro:unless value="$(eval robot_mode == 'calibration')">
        <limit upper="0.03" lower="-0.03" effort="100" velocity="100"/>
      </xacro:unless>      
      <!-- custom extension -->
      <channel>A</channel>
      <mm_to_count>715.0</mm_to_count>
    </joint>
    
    <joint name="insertion_joint" type="prismatic">
      <origin xyz="0 0 0" rpy="0 0 0"/>
      <parent link="horizontal_link"/>
      <child link="needle_link"/>
      <axis xyz="0.0 1.0 0.0"/>
      <!-- conditional limits -->
      <xacro:if value="$(eval robot_mode == 'calibration')">
        <limit upper="1e6" lower="-1e6" effort="100" velocity="1e6"/>
      </xacro:if>
      <xacro:unless value="$(eval robot_mode == 'calibration')">
        <limit upper="${insertion_upper_limit}" lower="0.0" effort="100" velocity="100"/>
      </xacro:unless>
      <!-- custom extension -->
      <channel>B</channel>
      <mm_to_count>-1574.8031</mm_to_count>
    </joint>

  </xacro:macro>

</robot>
